<?xml version = "1.0"?>
<robot name = "custom_bot">
    <link name = "base_link">
        <visual>
            <geometry>
                <box size = "0.5 0.3 0.1"/>
            </geometry>
            <material name = "chassis">
                <color rgba = "1 0 0 1"/>
            </material>
        </visual>
    </link>
    <link name = "caster_wheel">
        <visual>
            <geometry>
                <sphere radius = "0.05"/>
            </geometry>
            <material name = "caster">
                <color rgba = "0 0 1 1"/>
            </material>
        </visual>
    </link>
    <joint name = "caster_joint" type = "continuous">
        <axis xyz = "0 0 1"/>
        <parent link = "base_link"/>
        <child link = "caster_wheel"/>
        <origin xyz = "0.2 0 -0.05" rpy = "0 0 0"/>
    </joint>
</robot>